Workbook

Sheet JAN- TO FEB,MARCH
K1: DATE 13-04-2026
A2: ALLOTEE RENT PAYABLE DETAILS
A3: S.NOS. | B3: BRAND NAME | C3: SHOP NOS. | D3: ALLOTEE NAME | E3: SQ.FT. | F3: RENT MONTH OF Jan-2026 | G3: RENT MONTH OF Feb-2026 | H3: RENT MONTH OF MARCH-2026 | I3: RENT MONTH OF APRIL-2026 | J3: ALLOTEE RENT PAYABLE | K3: FOR THE MONTH OF JAN-26 TO FEB-26 | L3: REMARKS
A4: 1 | B4: HRY JEWELLERS | C4: G0059 | D4: RASHID HUSSAIN KHAN | E4: 96 | F4: 14400 | G4: 14400 | J4: =F4+G4 -> 28800 | K4: JAN-26 TO FEB-26 | L4: ADVANCE RENT ADJUSTED JAN TO FEB
C5: G0060 | D5: ABDUL WALI | E5: 96 | F5: 14400 | G5: 14400 | J5: =F5+G5 -> 28800 | K5: JAN-26 TO FEB-26 | L5: ADVANCE RENT ADJUSTED JAN TO FEB
A6: 2 | B6: ELENOR | C6: G0081 | D6: ALIYA BEGUM | E6: 96 | G6: 14400 | J6: =F6+G6 -> 14400 | K6: FEB-26 | L6: ISSHUED ON 07-05-2026
A7: 3 | B7: SALMAN SAIF | C7: G0050 | D7: TALAT ASHFAQ QURESHI | E7: 96 | G7: 17280 | J7: =F7+G7 -> 17280 | K7: FEB-26 | L7: ISSHUED ON 18-04-2026
C8: G0051 | D8: PROFESSIONAL MANAGEMENT | E8: 98 | G8: 17640 | J8: =F8+G8 -> 17640 | K8: FEB-26
C9: G0052 | D9: PROFESSIONAL MANAGEMENT | E9: 99 | G9: 17820 | J9: =F9+G9 -> 17820 | K9: FEB-26
C10: G0054 | D10: PROFESSIONAL MANAGEMENT | E10: 147 | G10: 26460 | J10: =F10+G10 -> 26460 | K10: FEB-26
C11: G0072 | D11: PROFESSIONAL MANAGEMENT | E11: 147 | G11: 26460 | J11: =F11+G11 -> 26460 | K11: FEB-26
C12: G0073 | D12: FALAKNAZ GROUP | E12: 99 | G12: 17820 | J12: =F12+G12 -> 17820 | K12: FEB-26
C13: G0074 | D13: PROFESSIONAL MANAGEMENT | E13: 192 | G13: 34560 | J13: =F13+G13 -> 34560 | K13: FEB-26
A14: 4 | B14: DOLLAR WORLD | C14: G0026 | D14: FALAKNAZ GROUP | E14: 144 | F14: 14400 | G14: 14400 | J14: =F14+G14 -> 28800 | K14: JAN-26 TO FEB-26
C15: G0027 | D15: MUHAMMAD IMRAN | E15: 96 | F15: 9600 | G15: 9600 | J15: =F15+G15 -> 19200 | K15: JAN-26 TO FEB-26
C16: G0028 | D16: HAMID ALI | E16: 96 | F16: 9600 | G16: 9600 | J16: =F16+G16 -> 19200 | K16: JAN-26 TO FEB-26
C17: G0030 | D17: ASIM QURESHI | SAQIB QURESHI | E17: 96 | F17: 9600 | G17: 9600 | J17: =F17+G17 -> 19200 | K17: JAN-26 TO FEB-26
C18: G0031 | D18: ASHFAQ AHMED SIDDIQUI | E18: 118 | F18: 11800 | G18: 11800 | J18: =F18+G18 -> 23600 | K18: JAN-26 TO FEB-26
C19: G0032 | D19: ASHFAQ AHMED SIDDIQUI | E19: 118 | F19: 11800 | G19: 11800 | J19: =F19+G19 -> 23600 | K19: JAN-26 TO FEB-26
C20: G0034 | D20: DANISH AHMED SIDDIQUI | E20: 96 | F20: 9600 | G20: 9600 | J20: =F20+G20 -> 19200 | K20: JAN-26 TO FEB-26 | L20: ISSHUED ON 22-04-2026
C21: G0036 | D21: KAY KAY GROUP | E21: 96 | F21: 9600 | G21: 9600 | J21: =F21+G21 -> 19200 | K21: JAN-26 TO FEB-26
C22: G0037 | D22: AZHAR ALI | E22: 96 | F22: 9600 | G22: 9600 | J22: =F22+G22 -> 19200 | K22: JAN-26 TO FEB-26
C23: G0038 | D23: FALAKNAZ GROUP | E23: 144 | F23: 14400 | G23: 14400 | J23: =F23+G23 -> 28800 | K23: JAN-26 TO FEB-26
A24: 5 | B24: BEMBENINE | C24: G0067 | D24: SOHAIL INTIZAR | E24: 96 | F24: 28800 | G24: 28800 | H24: 28800 | J24: =H24+G24+F24 -> 86400 | K24: JAN-26 TO FEB-26 ,MARCH-26
C25: G0068 | D25: MUHAMMAD RAFIQUE BURIRO | E25: 96 | F25: 28800 | G25: 28800 | H25: 28800 | J25: =H25+G25+F25 -> 86400 | K25: JAN-26 TO FEB-26 ,MARCH-26
C26: G0069 | D26: KAY KAY GROUP | E26: 99 | F26: 29700 | G26: 29700 | H26: 29700 | J26: =H26+G26+F26 -> 89100 | K26: JAN-26 TO FEB-26 ,MARCH-26
C27: G0071 | D27: KAY KAY GROUP | E27: 147 | F27: 44100 | G27: 44100 | H27: 44100 | J27: =H27+G27+F27 -> 132300 | K27: JAN-26 TO FEB-26 ,MARCH-26
A28: 7 | B28: NENDOS EXTENTION | C28: G0018 | D28: PROFESSIONAL MANAGEMENT | E28: 144 | G28: 28800 | H28: 28800 | J28: =G28+H28 -> 57600 | K28: FEB-26 ,MARCH-26,APRIL-26
C29: G0019 | D29: SYED RIZWAN HUSSAIN | E29: 98 | G29: 19600 | H29: 19600 | J29: =F29+G29 -> 19600 | K29: FEB-26
C30: G0020 | D30: SYED ASIF ALI | E30: 98 | G30: 19600 | H30: 19600 | J30: =F30+G30 -> 19600 | K30: FEB-26
C31: G0021 | D31: NIAZ AHMED | E31: 99 | G31: 19800 | H31: 19800 | J31: =F31+G31 -> 19800 | K31: FEB-26
C32: G0022 | D32: ISRAR AHMED | E32: 96 | G32: 19200 | H32: 19200 | J32: =F32+G32 -> 19200 | K32: FEB-26
C33: G0023 | D33: MUHAMMAD LAEEQ | E33: 96 | G33: 19200 | H33: 19200 | J33: =F33+G33 -> 19200 | K33: FEB-26 | L33: ISSHUED ON 16-04-2026
C34: G0025 | D34: SYED SAMMER ABBAS ZAIDI | E34: 147 | G34: 29400 | H34: 29400 | J34: =F34+G34 -> 29400 | K34: FEB-26
C35: G0040 | D35: PROFESSIONAL MANAGEMENT | E35: 147 | G35: 29400 | H35: 29400 | J35: =F35+G35 -> 29400 | K35: FEB-26
C36: G0041 | D36: MUHAMMAD ABID SALEEM UDDIN | E36: 99 | G36: 19800 | H36: 19800 | J36: =F36+G36 -> 19800 | K36: FEB-26
C37: G0043 | D37: PROFESSIONAL MANAGEMENT | E37: 192 | G37: 38400 | H37: 38400 | J37: =F37+G37 -> 38400 | K37: FEB-26
C38: G0044 | D38: FALAKNAZ GROUP | E38: 96 | G38: 19200 | H38: 19200 | J38: =F38+G38 -> 19200 | K38: FEB-26
C39: G0045 | D39: PROFESSIONAL MANAGEMENT | E39: 96 | G39: 19200 | H39: 19200 | J39: =F39+G39 -> 19200 | K39: FEB-26
A40: 8 | B40: STYLE IN | C40: G0082 | D40: SYED SAIF UR REHMAN | E40: 96 | G40: 28800 | J40: =F40+G40 -> 28800 | K40: FEB-26 | L40: ISSHUED ON 16-04-2026
...

Sheet Sheet4
B3: S.NOS. | C3: BRAND NAME | D3: SHOP NOS. | E3: ALLOTEE NAME | F3: SQ.FT. | G3: RENT MONTH OF JAN-2026 | L3: RENT MONTH OF FEB-2026 | Q3: RENT MONTH OF MARCH-2026 | V3: RENT MONTH OF APRIL-2026 | AA3: RENT MONTH OF MAY-2026
G4: AMOUNT | H4: CHQ NO. | I4: PAID | J4: DATE | K4: IN HAND | L4: AMOUNT | M4: CHQ NO. | N4: PAID | O4: DATE | P4: IN HAND | Q4: AMOUNT | R4: CHQ NO. | S4: PAID | T4: DATE | U4: IN HAND | V4: AMOUNT | W4: CHQ NO. | X4: PAID | Y4: DATE | Z4: IN HAND | AA4: AMOUNT | AB4: CHQ NO. | AC4: PAID | AD4: DATE | AE4: IN HAND
B5: 1 | C5: HRY JEWELLERS | D5: G0059 | E5: RASHID HUSSAIN KHAN | F5: 96 | H5: 33394909 | M5: 33394910 | R5: - | T5: - | W5: - | Y5: - | AB5: - | AD5: -
D6: G0060 | E6: ABDUL WALI | F6: 96 | H6: 33394911 | M6: 33394912 | R6: - | T6: - | W6: - | Y6: - | AB6: - | AD6: -
B7: 2 | C7: ELENOR | D7: G0081 | E7: ALIYA BEGUM | F7: 96 | H7: - | J7: - | M7: 33394908 | O7: 46208 | R7: 33649747 | T7: 18-06-2026 | W7: 33394946 | Y7: 27-06-2026 | AB7: 33394947 | AD7: 27-06-2026
B8: 3 | C8: SALMAN SAIF | D8: G0050 | E8: TALAT ASHFAQ QURESHI | F8: 96 | H8: - | J8: - | M8: 33394913 | O8: 22-04-26 | R8: - | T8: - | W8: - | Y8: - | AB8: - | AD8: -
D9: G0051 | E9: PROFESSIONAL MANAGEMENT | F9: 98 | H9: - | J9: - | M9: 33649726 | R9: - | T9: - | W9: - | Y9: - | AB9: - | AD9: -
D10: G0052 | E10: PROFESSIONAL MANAGEMENT | F10: 99 | H10: - | J10: - | M10: 33649727 | R10: - | T10: - | W10: - | Y10: - | AB10: - | AD10: -
D11: G0054 | E11: PROFESSIONAL MANAGEMENT | F11: 147 | H11: - | J11: - | M11: 33649728 | R11: - | T11: - | W11: - | Y11: - | AB11: - | AD11: -
D12: G0072 | E12: PROFESSIONAL MANAGEMENT | F12: 147 | H12: - | J12: - | M12: 33649729 | R12: - | T12: - | W12: - | Y12: - | AB12: - | AD12: -
D13: G0073 | E13: FALAKNAZ GROUP | F13: 99 | H13: - | J13: - | M13: 33649730 | R13: - | T13: - | W13: - | Y13: - | AB13: - | AD13: -
D14: G0074 | E14: PROFESSIONAL MANAGEMENT | F14: 192 | H14: - | J14: - | M14: 33649731 | R14: - | T14: - | W14: - | Y14: - | AB14: - | AD14: -
B15: 4 | C15: DOLLAR WORLD | D15: G0026 | E15: FALAKNAZ GROUP | F15: 144 | H15: 33649732 | M15: 33649733 | R15: - | T15: - | W15: - | Y15: - | AB15: - | AD15: -
D16: G0027 | E16: MUHAMMAD IMRAN | F16: 96 | H16: 33394914 | M16: 33394915 | R16: 33649748 | W16: 33649770 | AB16: 33649785
D17: G0028 | E17: HAMID ALI | F17: 96 | H17: 33394916 | M17: 33394917 | R17: 33649749 | W17: 33649769 | AB17: 33649786
D18: G0030 | E18: ASIM QURESHI | SAQIB QURESHI | F18: 96 | H18: 33394926 | M18: 33394927 | R18: 33649750 | W18: 33649771 | AB18: 33649787
D19: G0031 | E19: ASHFAQ AHMED SIDDIQUI | F19: 118 | H19: 33394918 | M19: 33394919 | R19: 33649751 | W19: 33649772 | AB19: 33649788
D20: G0032 | E20: ASHFAQ AHMED SIDDIQUI | F20: 118 | H20: 33394920 | M20: 33394921 | R20: 33649752 | W20: 33649773 | AB20: 33649789
D21: G0034 | E21: DANISH AHMED SIDDIQUI | F21: 96 | H21: 33394923 | J21: 22-04-26 | O21: 22-04-26 | R21: 33649753 | T21: 25-05-26 | W21: 33649774 | Y21: 27-07-2026 | AB21: 33649790 | AD21: 27-07-2026
D22: G0036 | E22: KAY KAY GROUP | F22: 96 | H22: 33649734 | M22: 33649735 | R22: - | T22: - | W22: - | Y22: - | AB22: - | AD22: -
D23: G0037 | E23: AZHAR ALI | F23: 96 | H23: 33394924 | M23: 33394925 | R23: 33649754 | W23: 33649775 | AB23: 33649791
D24: G0038 | E24: FALAKNAZ GROUP | F24: 144 | H24: 33649736 | M24: 33649737 | R24: - | T24: - | W24: - | Y24: - | AB24: - | AD24: -
B25: 5 | C25: BEMBENINE | D25: G0067 | E25: SOHAIL INTIZAR | F25: 96 | H25: 33394928 | M25: 33394929 | R25: 33649763 | W25: 33649783 | AB25: 33649798
D26: G0068 | E26: MUHAMMAD RAFIQUE BURIRO | F26: 96 | H26: 33394930 | M26: 33394931 | R26: 33649764 | W26: 33649784 | AB26: 33649799
D27: G0069 | E27: KAY KAY GROUP | F27: 99 | H27: 33649738 | M27: 33649739 | R27: - | T27: - | W27: - | Y27: - | AB27: - | AD27: -
D28: G0071 | E28: KAY KAY GROUP | F28: 147 | H28: 33649740 | M28: 33649741 | R28: - | T28: - | W28: - | Y28: - | AB28: - | AD28: -
B29: 6 | C29: NENDOS EXTENTION | D29: G0018 | E29: PROFESSIONAL MANAGEMENT | F29: 144 | H29: - | J29: - | M29: 33649742 | R29: - | T29: - | W29: - | Y29: - | AB29: - | AD29: -
D30: G0019 | E30: SYED RIZWAN HUSSAIN | F30: 98 | H30: - | J30: - | M30: 33394932 | O30: HOLD | R30: 33649755 | T30: HOLD | W30: 33649776 | AB30: 33649792
D31: G0020 | E31: SYED ASIF ALI | F31: 98 | H31: - | J31: - | M31: 33394933 | R31: 33649756 | W31: 33649777 | AB31: 33649793
D32: G0021 | E32: NIAZ AHMED | F32: 99 | H32: - | J32: - | M32: 33394934 | O32: 21-05-26 | R32: 33649757 | T32: 46271 | W32: 33649778 | Y32: 46088 | AB32: 33649794 | AD32: 46088
D33: G0022 | E33: RIAZ AHMED (ISRAR AHMED) | F33: 96 | H33: - | J33: - | M33: 33649765 | O33: 46271 | R33: 33649758 | T33: 46271 | W33: 33649800 | Y33: 46088 | AB33: 33649801 | AD33: 46088
D34: G0023 | E34: MUHAMMAD LAEEQ | F34: 96 | H34: - | J34: - | M34: 33394936 | O34: 20-04-26 | R34: 33649759 | T34: 21-05-26 | W34: 33649780 | Y34: 46060 | AB34: 33649795 | AD34: 46060
D35: G0025 | E35: SYED SAMMER ABBAS ZAIDI | F35: 147 | H35: - | J35: - | M35: 33394937 | R35: 33649760 | W35: 33649781 | AB35: 33649796
D36: G0040 | E36: PROFESSIONAL MANAGEMENT | F36: 147 | H36: - | J36: - | M36: 33649743 | R36: - | T36: - | W36: - | Y36: - | AB36: - | AD36: -
D37: G0041 | E37: MUHAMMAD ABID SALEEM UDDIN | F37: 99 | H37: - | J37: - | M37: 33394938 | R37: 33649761 | W37: 33649782 | AB37: 33649797
D38: G0043 | E38: PROFESSIONAL MANAGEMENT | F38: 192 | H38: - | J38: - | M38: 33649744 | R38: - | T38: - | W38: - | Y38: - | AB38: - | AD38: -
D39: G0044 | E39: FALAKNAZ GROUP | F39: 96 | H39: - | J39: - | M39: 33649745 | R39: - | T39: - | W39: - | Y39: - | AB39: - | AD39: -
D40: G0045 | E40: PROFESSIONAL MANAGEMENT | F40: 96 | H40: - | J40: - | M40: 33649746 | R40: - | T40: - | W40: - | Y40: - | AB40: - | AD40: -
B41: 7 | C41: STYLE IN | D41: G0082 | E41: SYED SAIF UR REHMAN | F41: 96 | H41: - | J41: - | M41: 33394907 | O41: 17-04-26 | R41: 33649762 | T41: 22-05-26
B43: TOTAL | H43: 0 | M43: 0 | R43: 0 | W43: =SUM(W5:W42) -> 571791391
...

Sheet Sheet5
B4: ALLOTTEES RENT SUMMARY
B5: MONTHS | C5: RENT AMOUNT | D5: RENT PAID | E5: BALANCE
B6: JAN | C6: =Sheet4!G87 -> 270200 | D6: =Sheet4!I87 -> 9600 | E6: =C6-D6 -> 260600
B7: FEB | C7: =Sheet4!G130 -> 753040 | D7: =Sheet4!I130 -> 128280 | E7: =C7-D7 -> 624760
B8: MARCH | C8: =Sheet4!G175 -> 318400 | D8: =Sheet4!I175 -> 110400 | E8: =C8-D8 -> 208000
B9: APRIL | C9: =Sheet4!G219 -> 318400 | D9: =Sheet4!I219 -> 130000 | E9: =C9-D9 -> 188400
B10: MAY | C10: =Sheet4!G264 -> 318400 | D10: =Sheet4!I264 -> 130000 | E10: =C10-D10 -> 188400
B11: TOTAL | C11: =SUM(C6:C10) -> 1978440 | D11: =SUM(D6:D10) -> 508280 | E11: =SUM(E6:E10) -> 1470160

Sheet ISSUES CHQS
B5: S.NOS. | C5: BRAND NAME | D5: SHOP NOS. | E5: ALLOTEE NAME | F5: SQ.FT. | G5: RENT MONTH OF Jan-2026 | I5: RENT MONTH OF Feb-2026 | K5: RENT MONTH OF MARCH-2026 | M5: RENT MONTH OF APRIL-2026 | O5: RENT MONTH OF MAY-2026
G6: CHQ NO. | H6: DATE | I6: CHQ NO. | J6: DATE | K6: CHQ NO. | L6: DATE | M6: CHQ NO. | N6: DATE | O6: CHQ NO. | P6: DATE | U6: ALLOTEE RENT PAYABLE | V6: FOR THE MONTH OF JAN-26 TO FEB-26 | W6: REMARKS
B7: 1 | C7: HRY JEWELLERS | D7: G0059 | E7: RASHID HUSSAIN KHAN | F7: 96 | G7: 33394909 | I7: 33394910 | K7: - | L7: - | M7: - | N7: - | O7: - | P7: - | V7: JAN-26 TO FEB-26 | W7: ADVANCE RENT ADJUSTED JAN TO FEB
D8: G0060 | E8: ABDUL WALI | F8: 96 | G8: 33394911 | I8: 33394912 | K8: - | L8: - | M8: - | N8: - | O8: - | P8: - | V8: JAN-26 TO FEB-26 | W8: ADVANCE RENT ADJUSTED JAN TO FEB
B9: 2 | C9: ELENOR | D9: G0081 | E9: ALIYA BEGUM | F9: 96 | G9: - | H9: - | I9: 33394908 | J9: 46208 | K9: 33649747 | L9: 18-06-2026 | M9: 33394946 | N9: 27-06-2026 | O9: 33394947 | P9: 27-06-2026 | V9: FEB-26
B10: 3 | C10: SALMAN SAIF | D10: G0050 | E10: TALAT ASHFAQ QURESHI | F10: 96 | G10: - | H10: - | I10: 33394913 | J10: 22-04-26 | K10: - | L10: - | M10: - | N10: - | O10: - | P10: - | V10: FEB-26
D11: G0051 | E11: PROFESSIONAL MANAGEMENT | F11: 98 | G11: - | H11: - | I11: 33649726 | K11: - | L11: - | M11: - | N11: - | O11: - | P11: - | V11: FEB-26
D12: G0052 | E12: PROFESSIONAL MANAGEMENT | F12: 99 | G12: - | H12: - | I12: 33649727 | K12: - | L12: - | M12: - | N12: - | O12: - | P12: - | V12: FEB-26
D13: G0054 | E13: PROFESSIONAL MANAGEMENT | F13: 147 | G13: - | H13: - | I13: 33649728 | K13: - | L13: - | M13: - | N13: - | O13: - | P13: - | V13: FEB-26
D14: G0072 | E14: PROFESSIONAL MANAGEMENT | F14: 147 | G14: - | H14: - | I14: 33649729 | K14: - | L14: - | M14: - | N14: - | O14: - | P14: - | V14: FEB-26
D15: G0073 | E15: FALAKNAZ GROUP | F15: 99 | G15: - | H15: - | I15: 33649730 | K15: - | L15: - | M15: - | N15: - | O15: - | P15: - | V15: FEB-26
D16: G0074 | E16: PROFESSIONAL MANAGEMENT | F16: 192 | G16: - | H16: - | I16: 33649731 | K16: - | L16: - | M16: - | N16: - | O16: - | P16: - | V16: FEB-26
B17: 4 | C17: DOLLAR WORLD | D17: G0026 | E17: FALAKNAZ GROUP | F17: 144 | G17: 33649732 | I17: 33649733 | K17: - | L17: - | M17: - | N17: - | O17: - | P17: - | V17: JAN-26 TO FEB-26
D18: G0027 | E18: MUHAMMAD IMRAN | F18: 96 | G18: 33394914 | I18: 33394915 | K18: 33649748 | M18: 33649770 | O18: 33649785 | V18: JAN-26 TO FEB-26
D19: G0028 | E19: HAMID ALI | F19: 96 | G19: 33394916 | I19: 33394917 | K19: 33649749 | M19: 33649769 | O19: 33649786 | V19: JAN-26 TO FEB-26
D20: G0030 | E20: ASIM QURESHI | SAQIB QURESHI | F20: 96 | G20: 33394926 | I20: 33394927 | K20: 33649750 | M20: 33649771 | O20: 33649787 | V20: JAN-26 TO FEB-26
D21: G0031 | E21: ASHFAQ AHMED SIDDIQUI | F21: 118 | G21: 33394918 | I21: 33394919 | K21: 33649751 | M21: 33649772 | O21: 33649788 | V21: JAN-26 TO FEB-26
D22: G0032 | E22: ASHFAQ AHMED SIDDIQUI | F22: 118 | G22: 33394920 | I22: 33394921 | K22: 33649752 | M22: 33649773 | O22: 33649789 | V22: JAN-26 TO FEB-26
D23: G0034 | E23: DANISH AHMED SIDDIQUI | F23: 96 | G23: 33394923 | H23: 22-04-26 | J23: 22-04-26 | K23: 33649753 | L23: 25-05-26 | M23: 33649774 | N23: 27-07-2026 | O23: 33649790 | P23: 27-07-2026 | V23: JAN-26 TO FEB-26
D24: G0036 | E24: KAY KAY GROUP | F24: 96 | G24: 33649734 | I24: 33649735 | K24: - | L24: - | M24: - | N24: - | O24: - | P24: - | V24: JAN-26 TO FEB-26
D25: G0037 | E25: AZHAR ALI | F25: 96 | G25: 33394924 | I25: 33394925 | K25: 33649754 | M25: 33649775 | O25: 33649791 | V25: JAN-26 TO FEB-26
D26: G0038 | E26: FALAKNAZ GROUP | F26: 144 | G26: 33649736 | I26: 33649737 | K26: - | L26: - | M26: - | N26: - | O26: - | P26: - | V26: JAN-26 TO FEB-26
B27: 5 | C27: BEMBENINE | D27: G0067 | E27: SOHAIL INTIZAR | F27: 96 | G27: 33394928 | I27: 33394929 | K27: 33649763 | M27: 33649783 | O27: 33649798 | V27: JAN-26 TO FEB-26 ,MARCH-26
D28: G0068 | E28: MUHAMMAD RAFIQUE BURIRO | F28: 96 | G28: 33394930 | I28: 33394931 | K28: 33649764 | M28: 33649784 | O28: 33649799 | V28: JAN-26 TO FEB-26 ,MARCH-26
D29: G0069 | E29: KAY KAY GROUP | F29: 99 | G29: 33649738 | I29: 33649739 | K29: - | L29: - | M29: - | N29: - | O29: - | P29: - | V29: JAN-26 TO FEB-26 ,MARCH-26
D30: G0071 | E30: KAY KAY GROUP | F30: 147 | G30: 33649740 | I30: 33649741 | K30: - | L30: - | M30: - | N30: - | O30: - | P30: - | V30: JAN-26 TO FEB-26 ,MARCH-26
B31: 6 | C31: NENDOS EXTENTION | D31: G0018 | E31: PROFESSIONAL MANAGEMENT | F31: 144 | G31: - | H31: - | I31: 33649742 | K31: - | L31: - | M31: - | N31: - | O31: - | P31: - | V31: FEB-26 ,MARCH-26,APRIL-26
D32: G0019 | E32: SYED RIZWAN HUSSAIN | F32: 98 | G32: - | H32: - | I32: 33394932 | J32: HOLD | K32: 33649755 | L32: HOLD | M32: 33649776 | O32: 33649792 | V32: FEB-26 | X32: 3002386547
D33: G0020 | E33: SYED ASIF ALI | F33: 98 | G33: - | H33: - | I33: 33394933 | K33: 33649756 | M33: 33649777 | O33: 33649793 | V33: FEB-26
D34: G0021 | E34: NIAZ AHMED | F34: 99 | G34: - | H34: - | I34: 33394934 | J34: 21-05-26 | K34: 33649757 | L34: 46271 | M34: 33649778 | N34: 46088 | O34: 33649794 | P34: 46088 | V34: FEB-26
D35: G0022 | E35: ISRAR AHMED | F35: 96 | G35: - | H35: - | I35: 33649765 | J35: 46271 | K35: 33649758 | L35: 46271 | M35: 33649800 | N35: 46088 | O35: 33649801 | P35: 46088 | V35: FEB-26
D36: G0023 | E36: MUHAMMAD LAEEQ | F36: 96 | G36: - | H36: - | I36: 33394936 | J36: 20-04-26 | K36: 33649759 | L36: 21-05-26 | M36: 33649780 | N36: 46060 | O36: 33649795 | P36: 46060 | V36: FEB-26
D37: G0025 | E37: SYED SAMMER ABBAS ZAIDI | F37: 147 | G37: - | H37: - | I37: 33394937 | K37: 33649760 | M37: 33649781 | O37: 33649796 | V37: FEB-26
D38: G0040 | E38: PROFESSIONAL MANAGEMENT | F38: 147 | G38: - | H38: - | I38: 33649743 | K38: - | L38: - | M38: - | N38: - | O38: - | P38: - | V38: FEB-26
D39: G0041 | E39: MUHAMMAD ABID SALEEM UDDIN | F39: 99 | G39: - | H39: - | I39: 33394938 | K39: 33649761 | M39: 33649782 | O39: 33649797 | V39: FEB-26
D40: G0043 | E40: PROFESSIONAL MANAGEMENT | F40: 192 | G40: - | H40: - | I40: 33649744 | K40: - | L40: - | M40: - | N40: - | O40: - | P40: - | V40: FEB-26
D41: G0044 | E41: FALAKNAZ GROUP | F41: 96 | G41: - | H41: - | I41: 33649745 | K41: - | L41: - | M41: - | N41: - | O41: - | P41: - | V41: FEB-26
D42: G0045 | E42: PROFESSIONAL MANAGEMENT | F42: 96 | G42: - | H42: - | I42: 33649746 | K42: - | L42: - | M42: - | N42: - | O42: - | P42: - | V42: FEB-26
B43: 7 | C43: STYLE IN | D43: G0082 | E43: SYED SAIF UR REHMAN | F43: 96 | G43: - | H43: - | I43: 33394907 | J43: 17-04-26 | K43: 33649762 | L43: 22-05-26 | V43: FEB-26
B45: TOTAL | G45: 0 | I45: 0 | K45: 0 | M45: =SUM(M7:M44) -> 571791391 | U45: =SUM(U7:U44) -> 0
...

Sheet APR-MAY
B4: LIST OF ALLOTTEES RENT CHEQUE APPROVAL SHEET | J4: LIST OF ALLOTTEES RENT CHEQUE APPROVAL SHEET
B5: S.NO | C5: DESCRCIPTION | D5: CHEQUE NO | E5: CHEQUE DATE | F5: BANK NAME | G5: AMOUNT | J5: S.NO | K5: DESCRCIPTION | L5: CHEQUE NO | M5: CHEQUE DATE | N5: BANK NAME | O5: AMOUNT
B6: 1 | C6: CHEQUE PAID TO ALLOTEE (ALIYA BEGUM ) AGAINST SHOP RENT FOR THE MONTH OF APRIL-2026 (SHOP #G-81) | D6: 33394946 | F6: DUBAI ISLAMIC BANK | G6: 14400 | J6: 1 | K6: CHEQUE PAID TO ALLOTEE (ALIYA BEGUM ) AGAINST SHOP RENT FOR THE MONTH OF MAY-2026 (SHOP #G-81) | L6: 33394947 | N6: DUBAI ISLAMIC BANK | O6: 14400
B7: 2 | C7: CHEQUE PAID TO ALLOTEE (MUHAMMAD IMRAN ) AGAINST SHOP RENT FOR THE MONTH OF APRIL-2026 (SHOP #G-27) | D7: 33649770 | F7: DUBAI ISLAMIC BANK | G7: 9600 | J7: 2 | K7: CHEQUE PAID TO ALLOTEE (MUHAMMAD IMRAN ) AGAINST SHOP RENT FOR THE MONTH OF MAY-2026 (SHOP #G-27) | L7: 33649785 | N7: DUBAI ISLAMIC BANK | O7: 9600
B8: 3 | C8: CHEQUE PAID TO ALLOTEE (HAMID ALI ) AGAINST SHOP RENT FOR THE MONTH OF APRIL-2026 (SHOP #G-28) | D8: 33649769 | F8: DUBAI ISLAMIC BANK | G8: 9600 | J8: 3 | K8: CHEQUE PAID TO ALLOTEE (HAMID ALI ) AGAINST SHOP RENT FOR THE MONTH OF MAY-2026 (SHOP #G-28) | L8: 33649786 | N8: DUBAI ISLAMIC BANK | O8: 9600
B9: 4 | C9: CHEQUE PAID TO ALLOTEE (ASIM QURESHI /SAQIB QURESHI) AGAINST SHOP RENT FOR THE MONTH OF APRIL-2026 (SHOP #G-30) | D9: 33649771 | F9: DUBAI ISLAMIC BANK | G9: 9600 | J9: 4 | K9: CHEQUE PAID TO ALLOTEE (ASIM QURESHI /SAQIB QURESHI) AGAINST SHOP RENT FOR THE MONTH OF MAY-2026 (SHOP #G-30) | L9: 33649787 | N9: DUBAI ISLAMIC BANK | O9: 9600
B10: 5 | C10: CHEQUE PAID TO ALLOTEE (ASHFAQ AHMED SIDDIQUI ) AGAINST SHOP RENT FOR THE MONTH OF APRIL-2026 (SHOP #G-31) | D10: 33649772 | F10: DUBAI ISLAMIC BANK | G10: 11800 | J10: 5 | K10: CHEQUE PAID TO ALLOTEE (ASHFAQ AHMED SIDDIQUI ) AGAINST SHOP RENT FOR THE MONTH OF MAY-2026 (SHOP #G-31) | L10: 33649788 | N10: DUBAI ISLAMIC BANK | O10: 11800
B11: 6 | C11: CHEQUE PAID TO ALLOTEE (ASHFAQ AHMED SIDDIQUE ) AGAINST SHOP RENT FOR THE MONTH OF APRIL-2026 (SHOP #G-32) | D11: 33649773 | F11: DUBAI ISLAMIC BANK | G11: 11800 | J11: 6 | K11: CHEQUE PAID TO ALLOTEE (ASHFAQ AHMED SIDDIQUE ) AGAINST SHOP RENT FOR THE MONTH OF MAY-2026 (SHOP #G-32) | L11: 33649789 | N11: DUBAI ISLAMIC BANK | O11: 11800
B12: 7 | C12: CHEQUE PAID TO ALLOTEE (DANISH AHMED SIDDIQUE) AGAINST SHOP RENT FOR THE MONTH OF APRIL-2026 (SHOP #G-34) | D12: 33649774 | F12: DUBAI ISLAMIC BANK | G12: 9600 | J12: 7 | K12: CHEQUE PAID TO ALLOTEE (DANISH AHMED SIDDIQUE) AGAINST SHOP RENT FOR THE MONTH OF MAY-2026 (SHOP #G-34) | L12: 33649790 | N12: DUBAI ISLAMIC BANK | O12: 9600
B13: 8 | C13: CHEQUE PAID TO ALLOTEE (AZHAR ALI ) AGAINST SHOP RENT FOR THE MONTH OF APRIL-2026 (SHOP #G-37) | D13: 33649775 | F13: DUBAI ISLAMIC BANK | G13: 9600 | J13: 8 | K13: CHEQUE PAID TO ALLOTEE (AZHAR ALI ) AGAINST SHOP RENT FOR THE MONTH OF MAY-2026 (SHOP #G-37) | L13: 33649791 | N13: DUBAI ISLAMIC BANK | O13: 9600
B14: 9 | C14: CHEQUE PAID TO ALLOTEE (SYED RIZWAN HUSSAIN) AGAINST SHOP RENT FOR THE MONTH OF APRIL-2026 (SHOP #G-19) | D14: 33649776 | F14: DUBAI ISLAMIC BANK | G14: 19600 | J14: 9 | K14: CHEQUE PAID TO ALLOTEE (SYED RIZWAN HUSSAIN) AGAINST SHOP RENT FOR THE MONTH OF MAY-2026 (SHOP #G-19) | L14: 33649792 | N14: DUBAI ISLAMIC BANK | O14: 19600
B16: TOTAL AMOUNT | G16: =SUM(G6:G14) -> 105600 | J16: TOTAL AMOUNT | O16: =SUM(O6:O14) -> 105600
C25: PREPAID BY | E25: CHECKED BY | K25: PREPAID BY | M25: CHECKED BY
C33: VERIFIED BY | E33: APPROVED BY | K33: VERIFIED BY | M33: APPROVED BY
B37: LIST OF ALLOTTEES RENT CHEQUE APPROVAL SHEET | J37: LIST OF ALLOTTEES RENT CHEQUE APPROVAL SHEET
B38: S.NO | C38: DESCRCIPTION | D38: CHEQUE NO | E38: CHEQUE DATE | F38: BANK NAME | G38: AMOUNT | J38: S.NO | K38: DESCRCIPTION | L38: CHEQUE NO | M38: CHEQUE DATE | N38: BANK NAME | O38: AMOUNT
B39: 1 | C39: CHEQUE PAID TO ALLOTEE (SYED ASIF ALI) AGAINST SHOP RENT FOR THE MONTH OF APRIL-2026 (SHOP #G-20) | D39: 33649777 | F39: DUBAI ISLAMIC BANK | G39: 19600 | J39: 1 | K39: CHEQUE PAID TO ALLOTEE (SYED ASIF ALI) AGAINST SHOP RENT FOR THE MONTH OF MAY-2026 (SHOP #G-20) | L39: 33649793 | N39: DUBAI ISLAMIC BANK | O39: 19600
B40: 2 | C40: CHEQUE PAID TO ALLOTEE (NIAZ AHMED ) AGAINST SHOP RENT FOR THE MONTH OF APRIL-2026 (SHOP #G-21) | D40: 33649778 | F40: DUBAI ISLAMIC BANK | G40: 19200 | J40: 2 | K40: CHEQUE PAID TO ALLOTEE (NIAZ AHMED ) AGAINST SHOP RENT FOR THE MONTH OF MAY-2026 (SHOP #G-21) | L40: 33649794 | N40: DUBAI ISLAMIC BANK | O40: 19200
B41: 3 | C41: CHEQUE PAID TO ALLOTEE (RIAZ AHMED ) AGAINST SHOP RENT FOR THE MONTH OF APRIL-2026 (SHOP #G-22) | D41: 33649800 | F41: DUBAI ISLAMIC BANK | G41: 19200 | J41: 3 | K41: CHEQUE PAID TO ALLOTEE (RIAZ AHMED ) AGAINST SHOP RENT FOR THE MONTH OF MAY-2026 (SHOP #G-22) | L41: 33649801 | N41: DUBAI ISLAMIC BANK | O41: 19200
B42: 4 | C42: CHEQUE PAID TO ALLOTEE (MUHAMMAD LAEEQ ) AGAINST SHOP RENT FOR THE MONTH OF APRIL-2026 (SHOP #G-23) | D42: 33649780 | F42: DUBAI ISLAMIC BANK | G42: 19200 | J42: 4 | K42: CHEQUE PAID TO ALLOTEE (MUHAMMAD LAEEQ ) AGAINST SHOP RENT FOR THE MONTH OF MAY-2026 (SHOP #G-23) | L42: 33649795 | N42: DUBAI ISLAMIC BANK | O42: 19200
B43: 5 | C43: CHEQUE PAID TO ALLOTEE (SYED SAMEER ABBAS ZAIDI ) AGAINST SHOP RENT FOR THE MONTH OF APRIL-2026 (SHOP #G-25) | D43: 33649781 | F43: DUBAI ISLAMIC BANK | G43: 29400 | J43: 5 | K43: CHEQUE PAID TO ALLOTEE (SYED SAMEER ABBAS ZAIDI ) AGAINST SHOP RENT FOR THE MONTH OF MAY-2026 (SHOP #G-25) | L43: 33649796 | N43: DUBAI ISLAMIC BANK | O43: 29400
B44: 6 | C44: CHEQUE PAID TO ALLOTEE (MUHAMMAD ABID SALEEM UDDIN) AGAINST SHOP RENT FOR THE MONTH OF APRIL-2026 (SHOP #G-41) | D44: 33649782 | F44: DUBAI ISLAMIC BANK | G44: 19800 | J44: 6 | K44: CHEQUE PAID TO ALLOTEE (MUHAMMAD ABID SALEEM UDDIN) AGAINST SHOP RENT FOR THE MONTH OF MAY-2026 (SHOP #G-41) | L44: 33649797 | N44: DUBAI ISLAMIC BANK | O44: 19800
B45: 7 | C45: CHEQUE PAID TO ALLOTEE (SOHAIL INTEZAR ) AGAINST SHOP RENT FOR THE MONTH OF APRIL-2026 (SHOP #G-67) | D45: 33649783 | F45: DUBAI ISLAMIC BANK | G45: 28800 | J45: 7 | K45: CHEQUE PAID TO ALLOTEE (SOHAIL INTEZAR ) AGAINST SHOP RENT FOR THE MONTH OF MAY-2026 (SHOP #G-67) | L45: 33649798 | N45: DUBAI ISLAMIC BANK | O45: 28800
B46: 8 | C46: CHEQUE PAID TO ALLOTEE (MUHAMMAD RAFIQUE BURIRO ) AGAINST SHOP RENT FOR THE MONTH OF APRIL-2026 (SHOP #G-68) | D46: 33649784 | F46: DUBAI ISLAMIC BANK | G46: 28800 | J46: 8 | K46: CHEQUE PAID TO ALLOTEE (MUHAMMAD RAFIQUE BURIRO ) AGAINST SHOP RENT FOR THE MONTH OF MAY-2026 (SHOP #G-68) | L46: 33649799 | N46: DUBAI ISLAMIC BANK | O46: 28800
B48: TOTAL AMOUNT | G48: =SUM(G39:G46) -> 184000 | J48: TOTAL AMOUNT | O48: =SUM(O39:O46) -> 184000
K58: PREPAID BY | M58: CHECKED BY
C59: PREPAID BY | E59: CHECKED BY
K66: VERIFIED BY | M66: APPROVED BY
C67: VERIFIED BY | E67: APPROVED BY
B73: LIST OF ALLOTTEES RENT CHEQUE APPROVAL SHEET
B74: S.NO | C74: DESCRCIPTION | D74: CHEQUE NO | E74: CHEQUE DATE | F74: BANK NAME | G74: AMOUNT
B75: 1 | C75: CHEQUE PAID TO ALLOTEE (SYED SAIF UR REHMAN) AGAINST SHOP RENT FOR THE MONTH OF APRIL-2026 (SHOP #G-82) | F75: DUBAI ISLAMIC BANK | G75: 19600
B76: 2 | C76: CHEQUE PAID TO ALLOTEE (SYED SAIF UR REHMAN) AGAINST SHOP RENT FOR THE MONTH OF MAY-2026 (SHOP #G-82) | F76: DUBAI ISLAMIC BANK | G76: 19200
B86: PREPAID BY | D86: CHECKED BY
B94: VERIFIED BY | D94: APPROVED BY

Sheet JUNE
J4: LIST OF ALLOTTEES RENT CHEQUE APPROVAL SHEET
J5: S.NO | K5: DESCRCIPTION | L5: CHEQUE NO | M5: CHEQUE DATE | N5: BANK NAME | O5: AMOUNT
J6: 1 | K6: CHEQUE PAID TO ALLOTEE (ALIYA BEGUM ) AGAINST SHOP RENT FOR THE MONTH OF JUNE-2026 (SHOP #G-81) | L6: 33649802 | N6: DUBAI ISLAMIC BANK | O6: 14400
J7: 2 | K7: CHEQUE PAID TO ALLOTEE (MUHAMMAD IMRAN ) AGAINST SHOP RENT FOR THE MONTH OF JUNE-2026 (SHOP #G-27) | L7: 33649812 | N7: DUBAI ISLAMIC BANK | O7: 9600
J8: 3 | K8: CHEQUE PAID TO ALLOTEE (HAMID ALI ) AGAINST SHOP RENT FOR THE MONTH OF JUNE-2026 (SHOP #G-28) | L8: 33649813 | N8: DUBAI ISLAMIC BANK | O8: 9600
J9: 4 | K9: CHEQUE PAID TO ALLOTEE (ASIM QURESHI /SAQIB QURESHI) AGAINST SHOP RENT FOR THE MONTH OF JUNE-2026 (SHOP #G-30) | L9: 33649814 | N9: DUBAI ISLAMIC BANK | O9: 9600
J10: 5 | K10: CHEQUE PAID TO ALLOTEE (ASHFAQ AHMED SIDDIQUI ) AGAINST SHOP RENT FOR THE MONTH OF JUNE-2026 (SHOP #G-31) | L10: 33649815 | N10: DUBAI ISLAMIC BANK | O10: 11800
J11: 6 | K11: CHEQUE PAID TO ALLOTEE (ASHFAQ AHMED SIDDIQUE ) AGAINST SHOP RENT FOR THE MONTH OF JUNE-2026 (SHOP #G-32) | L11: 33649816 | N11: DUBAI ISLAMIC BANK | O11: 11800
J12: 7 | K12: CHEQUE PAID TO ALLOTEE (DANISH AHMED SIDDIQUE) AGAINST SHOP RENT FOR THE MONTH OF JUNE-2026 (SHOP #G-34) | L12: 33649817 | N12: DUBAI ISLAMIC BANK | O12: 9600
J13: 8 | K13: CHEQUE PAID TO ALLOTEE (AZHAR ALI ) AGAINST SHOP RENT FOR THE MONTH OF JUNE-2026 (SHOP #G-37) | L13: 33649818 | N13: DUBAI ISLAMIC BANK | O13: 9600
J14: 9 | K14: CHEQUE PAID TO ALLOTEE (SYED RIZWAN HUSSAIN) AGAINST SHOP RENT FOR THE MONTH OF JUNE-2026 (SHOP #G-19) | L14: 33649804 | N14: DUBAI ISLAMIC BANK | O14: 19600
B16: TOTAL AMOUNT | G16: =SUM(G6:G102) -> 91200 | J16: TOTAL AMOUNT | O16: =SUM(O6:O14) -> 105600
C25: PREPAID BY | E25: CHECKED BY | K25: PREPAID BY | M25: CHECKED BY
C33: VERIFIED BY | E33: APPROVED BY | K33: VERIFIED BY | M33: APPROVED BY
B37: LIST OF ALLOTTEES RENT CHEQUE APPROVAL SHEET | J37: LIST OF ALLOTTEES RENT CHEQUE APPROVAL SHEET
B38: S.NO | C38: DESCRCIPTION | D38: CHEQUE NO | E38: CHEQUE DATE | F38: BANK NAME | G38: AMOUNT | J38: S.NO | K38: DESCRCIPTION | L38: CHEQUE NO | M38: CHEQUE DATE | N38: BANK NAME | O38: AMOUNT
J39: 1 | K39: CHEQUE PAID TO ALLOTEE (SYED ASIF ALI) AGAINST SHOP RENT FOR THE MONTH OF JUNE-2026 (SHOP #G-20) | L39: 33649805 | N39: DUBAI ISLAMIC BANK | O39: 19600
J40: 2 | K40: CHEQUE PAID TO ALLOTEE (NIAZ AHMED ) AGAINST SHOP RENT FOR THE MONTH OF JUNE-2026 (SHOP #G-21) | L40: 33649806 | N40: DUBAI ISLAMIC BANK | O40: 19200
J41: 3 | K41: CHEQUE PAID TO ALLOTEE (RIAZ AHMED ) AGAINST SHOP RENT FOR THE MONTH OF JUNE-2026 (SHOP #G-22) | L41: 33649807 | N41: DUBAI ISLAMIC BANK | O41: 19200
J42: 4 | K42: CHEQUE PAID TO ALLOTEE (MUHAMMAD LAEEQ ) AGAINST SHOP RENT FOR THE MONTH OF JUNE-2026 (SHOP #G-23) | L42: 33649809 | N42: DUBAI ISLAMIC BANK | O42: 19200
J43: 5 | K43: CHEQUE PAID TO ALLOTEE (SYED SAMEER ABBAS ZAIDI ) AGAINST SHOP RENT FOR THE MONTH OF JUNE-2026 (SHOP #G-25) | L43: 33649810 | N43: DUBAI ISLAMIC BANK | O43: 29400
J44: 6 | K44: CHEQUE PAID TO ALLOTEE (MUHAMMAD ABID SALEEM UDDIN) AGAINST SHOP RENT FOR THE MONTH OF JUNE-2026 (SHOP #G-41) | L44: 33649811 | N44: DUBAI ISLAMIC BANK | O44: 19800
B45: 7 | C45: CHEQUE PAID TO ALLOTEE (SOHAIL INTEZAR ) AGAINST SHOP RENT FOR THE MONTH OF JUNE-2026 (SHOP #G-67) | D45: 0 | F45: DUBAI ISLAMIC BANK | G45: 28800 | J45: 7 | K45: CHEQUE PAID TO ALLOTEE (SOHAIL INTEZAR ) AGAINST SHOP RENT FOR THE MONTH OF JUNE-2026 (SHOP #G-67) | L45: 0 | N45: DUBAI ISLAMIC BANK | O45: 28800
B46: 8 | C46: CHEQUE PAID TO ALLOTEE (MUHAMMAD RAFIQUE BURIRO ) AGAINST SHOP RENT FOR THE MONTH OF JUNE-2026 (SHOP #G-68) | D46: 0 | F46: DUBAI ISLAMIC BANK | G46: 28800 | J46: 8 | K46: CHEQUE PAID TO ALLOTEE (MUHAMMAD RAFIQUE BURIRO ) AGAINST SHOP RENT FOR THE MONTH OF JUNE-2026 (SHOP #G-68) | L46: 0 | N46: DUBAI ISLAMIC BANK | O46: 28800
B48: TOTAL AMOUNT | G48: =SUM(G39:G46) -> 57600 | J48: TOTAL AMOUNT | O48: =SUM(O39:O46) -> 184000
C59: PREPAID BY | E59: CHECKED BY | K59: PREPAID BY | M59: CHECKED BY
C67: VERIFIED BY | E67: APPROVED BY | K67: VERIFIED BY | M67: APPROVED BY
B73: LIST OF ALLOTTEES RENT CHEQUE APPROVAL SHEET
B74: ELENOR
B75: S.NO | C75: DESCRCIPTION | D75: CHEQUE NO | E75: CHEQUE DATE | F75: BANK NAME | G75: AMOUNT
B76: 1 | C76: CHEQUE PAID TO ALLOTEE (ALIYA BEGUM ) AGAINST SHOP RENT FOR THE MONTH OF JUNE-2026 (SHOP #G-81) | D76: 33649802 | F76: DUBAI ISLAMIC BANK | G76: 14400
B77: TOTAL AMOUNT | G77: =G76 -> 14400
C86: PREPAID BY | E86: CHECKED BY
C94: VERIFIED BY | E94: APPROVED BY
B99: LIST OF ALLOTTEES RENT CHEQUE APPROVAL SHEET | J99: LIST OF ALLOTTEES RENT CHEQUE APPROVAL SHEET
B100: NENDO EXTENSION | J100: NENDO EXTENSION
B101: S.NO | C101: DESCRCIPTION | D101: CHEQUE NO | E101: CHEQUE DATE | F101: BANK NAME | G101: AMOUNT | J101: S.NO | K101: DESCRCIPTION | L101: CHEQUE NO | M101: CHEQUE DATE | N101: BANK NAME | O101: AMOUNT
B102: 1 | C102: CHEQUE PAID TO ALLOTEE (SYED RIZWAN HUSSAIN) AGAINST SHOP RENT FOR THE MONTH OF JUNE-2026 (SHOP #G-19) | D102: 33649804 | F102: DUBAI ISLAMIC BANK | G102: 19600 | J102: 1 | K102: CHEQUE PAID TO ALLOTEE (SYED RIZWAN HUSSAIN) AGAINST SHOP RENT FOR THE MONTH OF JULY-2026 (SHOP #G-19) | L102: 33649822 | N102: DUBAI ISLAMIC BANK | O102: 19600
B103: 2 | C103: CHEQUE PAID TO ALLOTEE (SYED ASIF ALI) AGAINST SHOP RENT FOR THE MONTH OF JUNE-2026 (SHOP #G-20) | D103: 33649805 | F103: DUBAI ISLAMIC BANK | G103: 19600 | J103: 2 | K103: CHEQUE PAID TO ALLOTEE (SYED ASIF ALI) AGAINST SHOP RENT FOR THE MONTH OF JULY-2026 (SHOP #G-20) | L103: 33649823 | N103: DUBAI ISLAMIC BANK | O103: 19600
B104: 3 | C104: CHEQUE PAID TO ALLOTEE (NIAZ AHMED ) AGAINST SHOP RENT FOR THE MONTH OF JUNE-2026 (SHOP #G-21) | D104: 33649806 | F104: DUBAI ISLAMIC BANK | G104: 19200 | J104: 3 | K104: CHEQUE PAID TO ALLOTEE (NIAZ AHMED ) AGAINST SHOP RENT FOR THE MONTH OF JULY-2026 (SHOP #G-21) | L104: 33649824 | N104: DUBAI ISLAMIC BANK | O104: 19200
...

Sheet JULY
C3: LIST OF ALLOTTEES RENT CHEQUE APPROVAL SHEET
C5: RENT MONTH OF JULY-2026
C7: S.NOS. | D7: BRAND NAME | E7: SHOP NOS. | F7: ALLOTEE NAME | G7: CHEQUE NO. | H7: CHEQUE DATE | I7: BANK | J7: AMOUNT
C9: 1 | D9: HIJABEEZ | E9: G0091 | F9: SYED ZAHEER AHMED ZAIDI | I9: DIB | J9: 40000
E10: G0092 | F10: FAISAL RASHEED | G10: POSSESION NOT YET | J10: 0
C11: 2 | D11: AH STYLE | E11: UG0158 | F11: MUHAMMAD ANAS MATIN | J11: 15000
C12: 3 | D12: MARFAN | E12: UG0159 | F12: HINA NAZ | J12: 15600
C13: 4 | D13: ROSHNI ABAYA | E13: UG0030 | F13: MUZAFFAR AHMED | G13: POSSESION NOT YET | J13: 0
E14: UG0031 | F14: TARIQ AHMED | J14: 5206
E15: UG0032 | F15: RAJA WAQAS SALEH & RAJA JAWAD | G15: POSSESION NOT YET | J15: 0
E16: UG0036 | F16: IRFAN AHMED KHAN | J16: 5423
C17: 5 | D17: DOLLAR WORLD | E17: G0027 | F17: MUHAMMAD IMRAN | J17: 9600
E18: G0028 | F18: HAMID ALI | J18: 9600
E19: G0030 | F19: ASIM QURESHI | SAQIB QURESHI | J19: 9600
E20: G0031 | F20: ASHFAQ AHMED SIDDIQUI | J20: 11800
E21: G0032 | F21: ASHFAQ AHMED SIDDIQUI | J21: 11800
E22: G0034 | F22: DANISH AHMED SIDDIQUI | J22: 9600
E23: G0037 | F23: AZHAR ALI | J23: 9600
C24: 6 | D24: STYLE IN | E24: G0082 | F24: SYED SAIF UR REHMAN | J24: 28800
C25: TOTAL | J25: =SUM(J9:J24) -> 181629
C33: LIST OF ALLOTTEES RENT CHEQUE APPROVAL SHEET
C35: RENT MONTH OF AUG-2026
C37: S.NOS. | D37: BRAND NAME | E37: SHOP NOS. | F37: ALLOTEE NAME | G37: CHEQUE NO. | H37: CHEQUE DATE | I37: BANK | J37: AMOUNT
C39: 1 | D39: HIJABEEZ | E39: G0091 | F39: SYED ZAHEER AHMED ZAIDI | J39: 40000 | K39: 0
E40: G0092 | F40: FAISAL RASHEED | H40: POSSESION NOT YET | J40: 40000 | K40: 0
C41: 2 | D41: AH STYLE | E41: UG0158 | F41: MUHAMMAD ANAS MATIN | J41: 15000 | K41: 0
C42: 3 | D42: MARFAN | E42: UG0159 | F42: HINA NAZ | J42: 15600 | K42: 0
C43: 4 | D43: ROSHNI ABAYA | E43: UG0030 | F43: MUZAFFAR AHMED | H43: POSSESION NOT YET | J43: 0 | K43: 0
E44: UG0031 | F44: TARIQ AHMED | J44: 5206 | K44: 0
E45: UG0032 | F45: RAJA WAQAS SALEH & RAJA JAWAD | H45: POSSESION NOT YET | J45: 0 | K45: 0
E46: UG0036 | F46: IRFAN AHMED KHAN | J46: 5423 | K46: 0
C47: 5 | D47: DOLLAR WORLD | E47: G0027 | F47: MUHAMMAD IMRAN | H47: POSSESION NOT YET | J47: 14400 | K47: 0
E48: G0028 | F48: HAMID ALI | J48: 14400 | K48: 0
E49: G0030 | F49: ASIM QURESHI | SAQIB QURESHI | J49: 14400 | K49: 0
E50: G0031 | F50: ASHFAQ AHMED SIDDIQUI | H50: POSSESION NOT YET | J50: 17700 | K50: 0
E51: G0032 | F51: ASHFAQ AHMED SIDDIQUI | H51: POSSESION NOT YET | J51: 17700 | K51: 0
E52: G0034 | F52: DANISH AHMED SIDDIQUI | J52: 14400 | K52: 0
E53: G0037 | F53: AZHAR ALI | H53: POSSESION NOT YET | J53: 14400 | K53: 0
C54: 6 | D54: CHILL APPAREL | E54: G0067 | F54: SOHAIL INTIZAR | J54: 31200 | K54: 0
E55: G0068 | F55: MUHAMMAD RAFIQUE BURIRO | H55: POSSESION NOT YET | J55: 0 | K55: 0
...

Sheet Sheet7

Sheet Sheet3
B4: LIST OF ALLOTTEES RENT CHEQUE APPROVAL SHEET | J4: LIST OF PROFRSSIONAL MANAGMENT RENT CHEQUE APPROVAL SHEET | S4: LIST OF KAY KAY GROUP RENT CHEQUE APPROVAL SHEET | AB4: LIST OF FALAKNAZ GROUP RENT CHEQUE APPROVAL SHEET
B5: S.NO | C5: DESCRCIPTION | D5: CHEQUE NO | E5: CHEQUE DATE | F5: BANK NAME | G5: AMOUNT | J5: S.NO | K5: DESCRCIPTION | L5: CHEQUE NO | M5: CHEQUE DATE | N5: BANK NAME | O5: AMOUNT | S5: S.NO | T5: DESCRCIPTION | U5: CHEQUE NO | V5: CHEQUE DATE | W5: BANK NAME | X5: AMOUNT | AB5: S.NO | AC5: DESCRCIPTION | AD5: CHEQUE NO | AE5: CHEQUE DATE | AF5: BANK NAME | AG5: AMOUNT
B6: 1 | C6: CHEQUE PAID TO ALLOTEE (PROFRSSIONAL MANAGMENT) AGAINST SHOP RENT FOR THE MONTH OF FEB-2026(SHOP #G-51) | D6: 33649726 | F6: DUBAI ISLAMIC BANK | G6: 17640 | J6: 1 | K6: CHEQUE PAID TO ALLOTEE (PROFRSSIONAL MANAGMENT) AGAINST SHOP RENT FOR THE MONTH OF FEB-2026(SHOP #G-51) | L6: 33649726 | N6: DUBAI ISLAMIC BANK | O6: 17640 | S6: 1 | T6: CHEQUE PAID TO ALLOTEE (KAY KAY GROUP ) AGAINST SHOP RENT FOR THE MONTH OF JAN-2026(SHOP #G-36) | U6: 33649734 | W6: DUBAI ISLAMIC BANK | X6: 9600 | AB6: 1 | AC6: CHEQUE PAID TO ALLOTEE (FALAKNAZ GROUP) AGAINST SHOP RENT FOR THE MONTH OF FEB-2026(SHOP #G-73) | AD6: 33649730 | AF6: DUBAI ISLAMIC BANK | AG6: 17820
B7: 2 | C7: CHEQUE PAID TO ALLOTEE (PROFRSSIONAL MANAGMENT) AGAINST SHOP RENT FOR THE MONTH OF FEB-2026(SHOP #G-52) | D7: 33649727 | F7: DUBAI ISLAMIC BANK | G7: 17820 | J7: 2 | K7: CHEQUE PAID TO ALLOTEE (PROFRSSIONAL MANAGMENT) AGAINST SHOP RENT FOR THE MONTH OF FEB-2026(SHOP #G-52) | L7: 33649727 | N7: DUBAI ISLAMIC BANK | O7: 17820 | S7: 2 | T7: CHEQUE PAID TO ALLOTEE (KAY KAY GROUP ) AGAINST SHOP RENT FOR THE MONTH OF FEB-2026(SHOP #G-36) | U7: 33649735 | W7: DUBAI ISLAMIC BANK | X7: 9600 | AB7: 2 | AC7: CHEQUE PAID TO ALLOTEE (FALAKNAZ GROUP) AGAINST SHOP RENT FOR THE MONTH OF JAN-2026(SHOP #G-26) | AD7: 33649732 | AF7: DUBAI ISLAMIC BANK | AG7: 14400
B8: 3 | C8: CHEQUE PAID TO ALLOTEE (PROFRSSIONAL MANAGMENT) AGAINST SHOP RENT FOR THE MONTH OF FEB-2026(SHOP #G-54) | D8: 33649728 | F8: DUBAI ISLAMIC BANK | G8: 26460 | J8: 3 | K8: CHEQUE PAID TO ALLOTEE (PROFRSSIONAL MANAGMENT) AGAINST SHOP RENT FOR THE MONTH OF FEB-2026(SHOP #G-54) | L8: 33649728 | N8: DUBAI ISLAMIC BANK | O8: 26460 | S8: 3 | T8: CHEQUE PAID TO ALLOTEE (KAY KAY GROUP ) AGAINST SHOP RENT FOR THE MONTH OF JAN-2026(SHOP #G-69) | U8: 33649738 | W8: DUBAI ISLAMIC BANK | X8: 29700 | AB8: 3 | AC8: CHEQUE PAID TO ALLOTEE (FALAKNAZ GROUP ) AGAINST SHOP RENT FOR THE MONTH OF FEB-2026(SHOP #G-26) | AD8: 33649733 | AF8: DUBAI ISLAMIC BANK | AG8: 14400
B9: 4 | C9: CHEQUE PAID TO ALLOTEE (PROFRSSIONAL MANAGMENT) AGAINST SHOP RENT FOR THE MONTH OF FEB-2026(SHOP #G-72) | D9: 33649729 | F9: DUBAI ISLAMIC BANK | G9: 26460 | J9: 4 | K9: CHEQUE PAID TO ALLOTEE (PROFRSSIONAL MANAGMENT) AGAINST SHOP RENT FOR THE MONTH OF FEB-2026(SHOP #G-72) | L9: 33649729 | N9: DUBAI ISLAMIC BANK | O9: 26460 | S9: 4 | T9: CHEQUE PAID TO ALLOTEE (KAY KAY GROUP ) AGAINST SHOP RENT FOR THE MONTH OF FEB-2026(SHOP #G-69) | U9: 33649739 | W9: DUBAI ISLAMIC BANK | X9: 29700 | AB9: 4 | AC9: CHEQUE PAID TO ALLOTEE (FALAKNAZ GROUP ) AGAINST SHOP RENT FOR THE MONTH OF JAN-2026(SHOP #G-38) | AD9: 33649736 | AF9: DUBAI ISLAMIC BANK | AG9: 14400
B10: 5 | C10: CHEQUE PAID TO ALLOTEE (FALAKNAZ GROUP) AGAINST SHOP RENT FOR THE MONTH OF FEB-2026(SHOP #G-73) | D10: 33649730 | F10: DUBAI ISLAMIC BANK | G10: 17820 | J10: 5 | K10: CHEQUE PAID TO ALLOTEE (PROFESSIONAL MANAGMENT ) AGAINST SHOP RENT FOR THE MONTH OF FEB-2026(SHOP #G-74) | L10: 33649731 | N10: DUBAI ISLAMIC BANK | O10: 34560 | S10: 5 | T10: CHEQUE PAID TO ALLOTEE (KAY KAY GROUP ) AGAINST SHOP RENT FOR THE MONTH OF JAN-2026(SHOP #G-71) | U10: 33649740 | W10: DUBAI ISLAMIC BANK | X10: 44100 | AB10: 5 | AC10: CHEQUE PAID TO ALLOTEE (FALAKNAZ GROUP ) AGAINST SHOP RENT FOR THE MONTH OF FEB-2026(SHOP #G-38) | AD10: 33649737 | AF10: DUBAI ISLAMIC BANK | AG10: 14400
B11: 6 | C11: CHEQUE PAID TO ALLOTEE (PROFESSIONAL MANAGMENT ) AGAINST SHOP RENT FOR THE MONTH OF FEB-2026(SHOP #G-74) | D11: 33649731 | F11: DUBAI ISLAMIC BANK | G11: 34560 | J11: 6 | K11: CHEQUE PAID TO ALLOTEE (PROFRSSIONAL MANAGMENT) AGAINST SHOP RENT FOR THE MONTH OF FEB-2026(SHOP #G-18) | L11: 33649742 | N11: DUBAI ISLAMIC BANK | O11: 28800 | S11: 6 | T11: CHEQUE PAID TO ALLOTEE (KAY KAY GROUP ) AGAINST SHOP RENT FOR THE MONTH OF FEB-2026(SHOP #G-71) | U11: 33649741 | W11: DUBAI ISLAMIC BANK | X11: 44100 | AB11: 6 | AC11: CHEQUE PAID TO ALLOTEE (FALAKNAZ GROUP ) AGAINST SHOP RENT FOR THE MONTH OF FEB-2026(SHOP #G-44) | AD11: 33649745 | AF11: DUBAI ISLAMIC BANK | AG11: 19200
B12: 7 | C12: CHEQUE PAID TO ALLOTEE (FALAKNAZ GROUP) AGAINST SHOP RENT FOR THE MONTH OF JAN-2026(SHOP #G-26) | D12: 33649732 | F12: DUBAI ISLAMIC BANK | G12: 14400 | J12: 7 | K12: CHEQUE PAID TO ALLOTEE (PROFRSSIONAL MANAGMENT) AGAINST SHOP RENT FOR THE MONTH OF FEB-2026(SHOP #G-40) | L12: 33649743 | N12: DUBAI ISLAMIC BANK | O12: 29400 | S12: TOTAL AMOUNT | X12: =SUM(X2:X11) -> 166800 | AB12: TOTAL AMOUNT | AG12: =SUM(AG2:AG11) -> 94620
B13: 8 | C13: CHEQUE PAID TO ALLOTEE (FALAKNAZ GROUP ) AGAINST SHOP RENT FOR THE MONTH OF FEB-2026(SHOP #G-26) | D13: 33649733 | F13: DUBAI ISLAMIC BANK | G13: 14400 | J13: 8 | K13: CHEQUE PAID TO ALLOTEE (PROFRSSIONAL MANAGMENT) AGAINST SHOP RENT FOR THE MONTH OF FEB-2026(SHOP #G-43) | L13: 33649744 | N13: DUBAI ISLAMIC BANK | O13: 38400
B14: 9 | C14: CHEQUE PAID TO ALLOTEE (KAY KAY GROUP ) AGAINST SHOP RENT FOR THE MONTH OF JAN-2026(SHOP #G-36) | D14: 33649734 | F14: DUBAI ISLAMIC BANK | G14: 9600 | J14: 9 | K14: CHEQUE PAID TO ALLOTEE (PROFRSSIONAL MANAGMENT) AGAINST SHOP RENT FOR THE MONTH OF FEB-2026(SHOP #G-45) | L14: 33649746 | N14: DUBAI ISLAMIC BANK | O14: 19200
B15: 10 | C15: CHEQUE PAID TO ALLOTEE (KAY KAY GROUP ) AGAINST SHOP RENT FOR THE MONTH OF FEB-2026(SHOP #G-36) | D15: 33649735 | F15: DUBAI ISLAMIC BANK | G15: 9600 | J15: TOTAL AMOUNT | O15: =SUM(O5:O14) -> 238740
C16: TOTAL AMOUNT | G16: =SUM(G6:G15) -> 188760
C18: PREPAID BY | E18: CHECKED BY
C21: VERIFIED BY | E21: APPROVED BY
B24: LIST OF ALLOTTEES RENT CHEQUE APPROVAL SHEET
B25: S.NO | C25: DESCRCIPTION | D25: CHEQUE NO | E25: CHEQUE DATE | F25: BANK NAME | G25: AMOUNT | H25: REMARKS
B26: 1 | C26: CHEQUE PAID TO ALLOTEE (FALAKNAZ GROUP ) AGAINST SHOP RENT FOR THE MONTH OF JAN-2026(SHOP #G-38) | D26: 33649736 | F26: DUBAI ISLAMIC BANK | G26: 14400
B27: 2 | C27: CHEQUE PAID TO ALLOTEE (FALAKNAZ GROUP ) AGAINST SHOP RENT FOR THE MONTH OF FEB-2026(SHOP #G-38) | D27: 33649737 | F27: DUBAI ISLAMIC BANK | G27: 14400
B28: 3 | C28: CHEQUE PAID TO ALLOTEE (KAY KAY GROUP ) AGAINST SHOP RENT FOR THE MONTH OF JAN-2026(SHOP #G-69) | D28: 33649738 | F28: DUBAI ISLAMIC BANK | G28: 29700
B29: 4 | C29: CHEQUE PAID TO ALLOTEE (KAY KAY GROUP ) AGAINST SHOP RENT FOR THE MONTH OF FEB-2026(SHOP #G-69) | D29: 33649739 | F29: DUBAI ISLAMIC BANK | G29: 29700
B30: 5 | C30: CHEQUE PAID TO ALLOTEE (KAY KAY GROUP ) AGAINST SHOP RENT FOR THE MONTH OF JAN-2026(SHOP #G-71) | D30: 33649740 | F30: DUBAI ISLAMIC BANK | G30: 44100
B31: 6 | C31: CHEQUE PAID TO ALLOTEE (KAY KAY GROUP ) AGAINST SHOP RENT FOR THE MONTH OF FEB-2026(SHOP #G-71) | D31: 33649741 | F31: DUBAI ISLAMIC BANK | G31: 44100
B32: 7 | C32: CHEQUE PAID TO ALLOTEE (PROFRSSIONAL MANAGMENT) AGAINST SHOP RENT FOR THE MONTH OF FEB-2026(SHOP #G-18) | D32: 33649742 | F32: DUBAI ISLAMIC BANK | G32: 28800
B33: 8 | C33: CHEQUE PAID TO ALLOTEE (PROFRSSIONAL MANAGMENT) AGAINST SHOP RENT FOR THE MONTH OF FEB-2026(SHOP #G-40) | D33: 33649743 | F33: DUBAI ISLAMIC BANK | G33: 29400
B34: 9 | C34: CHEQUE PAID TO ALLOTEE (PROFRSSIONAL MANAGMENT) AGAINST SHOP RENT FOR THE MONTH OF FEB-2026(SHOP #G-43) | D34: 33649744 | F34: DUBAI ISLAMIC BANK | G34: 38400
B35: 10 | C35: CHEQUE PAID TO ALLOTEE (FALAKNAZ GROUP ) AGAINST SHOP RENT FOR THE MONTH OF FEB-2026(SHOP #G-44) | D35: 33649745 | F35: DUBAI ISLAMIC BANK | G35: 19200
B36: 11 | C36: CHEQUE PAID TO ALLOTEE (PROFRSSIONAL MANAGMENT) AGAINST SHOP RENT FOR THE MONTH OF FEB-2026(SHOP #G-45) | D36: 33649746 | F36: DUBAI ISLAMIC BANK | G36: 19200
C37: TOTAL AMOUNT | G37: =SUM(G26:G36) -> 311400
C44: PREPAID BY | E44: CHECKED BY
B51: LIST OF PROFRSSIONAL MANAGMENT RENT CHEQUES
B52: S.NO | C52: DESCRCIPTION | D52: CHEQUE NO | E52: CHEQUE DATE | F52: BANK NAME | G52: AMOUNT | H52: REMARKS
B53: 1 | C53: CHEQUE PAID TO ALLOTEE (PROFRSSIONAL MANAGMENT) AGAINST SHOP RENT FOR THE MONTH OF FEB-2026(SHOP #G-51) | D53: 33649726 | F53: DUBAI ISLAMIC BANK | G53: 17640
B54: 2 | C54: CHEQUE PAID TO ALLOTEE (PROFRSSIONAL MANAGMENT) AGAINST SHOP RENT FOR THE MONTH OF FEB-2026(SHOP #G-52) | D54: 33649727 | F54: DUBAI ISLAMIC BANK | G54: 17820
B55: 3 | C55: CHEQUE PAID TO ALLOTEE (PROFRSSIONAL MANAGMENT) AGAINST SHOP RENT FOR THE MONTH OF FEB-2026(SHOP #G-54) | D55: 33649728 | F55: DUBAI ISLAMIC BANK | G55: 26460
B56: 4 | C56: CHEQUE PAID TO ALLOTEE (PROFRSSIONAL MANAGMENT) AGAINST SHOP RENT FOR THE MONTH OF FEB-2026(SHOP #G-72) | D56: 33649729 | F56: DUBAI ISLAMIC BANK | G56: 26460
B57: 5 | C57: CHEQUE PAID TO ALLOTEE (PROFESSIONAL MANAGMENT ) AGAINST SHOP RENT FOR THE MONTH OF FEB-2026(SHOP #G-74) | D57: 33649731 | F57: DUBAI ISLAMIC BANK | G57: 34560
B58: 6 | C58: CHEQUE PAID TO ALLOTEE (PROFRSSIONAL MANAGMENT) AGAINST SHOP RENT FOR THE MONTH OF FEB-2026(SHOP #G-18) | D58: 33649742 | F58: DUBAI ISLAMIC BANK | G58: 28800
B59: 7 | C59: CHEQUE PAID TO ALLOTEE (PROFRSSIONAL MANAGMENT) AGAINST SHOP RENT FOR THE MONTH OF FEB-2026(SHOP #G-40) | D59: 33649743 | F59: DUBAI ISLAMIC BANK | G59: 29400
B60: 8 | C60: CHEQUE PAID TO ALLOTEE (PROFRSSIONAL MANAGMENT) AGAINST SHOP RENT FOR THE MONTH OF FEB-2026(SHOP #G-43) | D60: 33649744 | F60: DUBAI ISLAMIC BANK | G60: 38400
...

Sheet MARCH-APR
A1: DATE 13-05-2026 | M1: DATE 20-06-2026 | X1: DATE 20-06-2026
A2: ALLOTEE RENT PAYABLE DETAILS | M2: ALLOTEE RENT PAYABLE DETAILS | X2: ALLOTEE RENT PAYABLE DETAILS
A3: S.NOS. | B3: BRAND NAME | C3: SHOP NOS. | D3: ALLOTEE NAME | E3: SQ.FT. | F3: RENT MONTH OF MARCH-2026 | G3: ALLOTEE RENT PAYABLE | H3: FOR THE MONTH OF MARCH-26 | I3: REMARKS | M3: S.NOS. | N3: BRAND NAME | O3: SHOP NOS. | P3: ALLOTEE NAME | Q3: SQ.FT. | R3: RENT MONTH OF APRIL-2026 | S3: ALLOTEE RENT PAYABLE | T3: REMARKS | X3: S.NOS. | Y3: BRAND NAME | Z3: SHOP NOS. | AA3: ALLOTEE NAME | AB3: SQ.FT. | AC3: RENT MONTH OF MAY-2026 | AD3: ALLOTEE RENT PAYABLE | AE3: REMARKS
A4: 1 | B4: ELENOR | C4: G0081 | D4: ALIYA BEGUM | E4: 96 | F4: 14400 | G4: =F4 -> 14400 | H4: 46082 | M4: 1 | N4: ELENOR | O4: G0081 | P4: ALIYA BEGUM | Q4: 96 | R4: 14400 | S4: =R4 -> 14400 | X4: 1 | Y4: ELENOR | Z4: G0081 | AA4: ALIYA BEGUM | AB4: 96 | AC4: 14400 | AD4: =AC4 -> 14400
A5: 2 | B5: DOLLAR WORLD | C5: G0026 | D5: FALAKNAZ GROUP | E5: 144 | F5: 14400 | G5: =F5 -> 14400 | H5: 46082 | M5: 2 | N5: DOLLAR WORLD | O5: G0026 | P5: FALAKNAZ GROUP | Q5: 144 | R5: 14400 | S5: =R5 -> 14400 | X5: 2 | Y5: DOLLAR WORLD | Z5: G0026 | AA5: FALAKNAZ GROUP | AB5: 144 | AC5: 14400 | AD5: =AC5 -> 14400
B6: DOLLAR WORLD | C6: G0027 | D6: MUHAMMAD IMRAN | E6: 96 | F6: 9600 | G6: =F6 -> 9600 | H6: 46082 | O6: G0027 | P6: MUHAMMAD IMRAN | Q6: 96 | R6: 9600 | S6: =R6 -> 9600 | Z6: G0027 | AA6: MUHAMMAD IMRAN | AB6: 96 | AC6: 9600 | AD6: =AC6 -> 9600
B7: DOLLAR WORLD | C7: G0028 | D7: HAMID ALI | E7: 96 | F7: 9600 | G7: =F7 -> 9600 | H7: 46082 | O7: G0028 | P7: HAMID ALI | Q7: 96 | R7: 9600 | S7: =R7 -> 9600 | Z7: G0028 | AA7: HAMID ALI | AB7: 96 | AC7: 9600 | AD7: =AC7 -> 9600
B8: DOLLAR WORLD | C8: G0030 | D8: ASIM QURESHI | SAQIB QURESHI | E8: 96 | F8: 9600 | G8: =F8 -> 9600 | H8: 46082 | O8: G0030 | P8: ASIM QURESHI | SAQIB QURESHI | Q8: 96 | R8: 9600 | S8: =R8 -> 9600 | Z8: G0030 | AA8: ASIM QURESHI | SAQIB QURESHI | AB8: 96 | AC8: 9600 | AD8: =AC8 -> 9600
B9: DOLLAR WORLD | C9: G0031 | D9: ASHFAQ AHMED SIDDIQUI | E9: 118 | F9: 11800 | G9: =F9 -> 11800 | H9: 46082 | O9: G0031 | P9: ASHFAQ AHMED SIDDIQUI | Q9: 118 | R9: 11800 | S9: =R9 -> 11800 | Z9: G0031 | AA9: ASHFAQ AHMED SIDDIQUI | AB9: 118 | AC9: 11800 | AD9: =AC9 -> 11800
B10: DOLLAR WORLD | C10: G0032 | D10: ASHFAQ AHMED SIDDIQUI | E10: 118 | F10: 11800 | G10: =F10 -> 11800 | H10: 46082 | O10: G0032 | P10: ASHFAQ AHMED SIDDIQUI | Q10: 118 | R10: 11800 | S10: =R10 -> 11800 | Z10: G0032 | AA10: ASHFAQ AHMED SIDDIQUI | AB10: 118 | AC10: 11800 | AD10: =AC10 -> 11800
B11: DOLLAR WORLD | C11: G0034 | D11: DANISH AHMED SIDDIQUI | E11: 96 | F11: 9600 | G11: =F11 -> 9600 | H11: 46082 | O11: G0034 | P11: DANISH AHMED SIDDIQUI | Q11: 96 | R11: 9600 | S11: =R11 -> 9600 | Z11: G0034 | AA11: DANISH AHMED SIDDIQUI | AB11: 96 | AC11: 9600 | AD11: =AC11 -> 9600
B12: DOLLAR WORLD | C12: G0036 | D12: KAY KAY GROUP | E12: 96 | F12: 9600 | G12: =F12 -> 9600 | H12: 46082 | O12: G0036 | P12: KAY KAY GROUP | Q12: 96 | R12: 9600 | S12: =R12 -> 9600 | Z12: G0036 | AA12: KAY KAY GROUP | AB12: 96 | AC12: 9600 | AD12: =AC12 -> 9600
B13: DOLLAR WORLD | C13: G0037 | D13: AZHAR ALI | E13: 96 | F13: 9600 | G13: =F13 -> 9600 | H13: 46082 | O13: G0037 | P13: AZHAR ALI | Q13: 96 | R13: 9600 | S13: =R13 -> 9600 | Z13: G0037 | AA13: AZHAR ALI | AB13: 96 | AC13: 9600 | AD13: =AC13 -> 9600
B14: DOLLAR WORLD | C14: G0038 | D14: FALAKNAZ GROUP | E14: 144 | F14: 14400 | G14: =F14 -> 14400 | H14: 46082 | O14: G0038 | P14: FALAKNAZ GROUP | Q14: 144 | R14: 14400 | S14: =R14 -> 14400 | Z14: G0038 | AA14: FALAKNAZ GROUP | AB14: 144 | AC14: 14400 | AD14: =AC14 -> 14400
A15: 3 | B15: NENDOS EXTENTION | C15: G0018 | D15: PROFESSIONAL MANAGEMENT | E15: 144 | F15: 28800 | G15: =F15 -> 28800 | H15: 46082 | M15: 3 | N15: NENDOS EXTENTION | O15: G0018 | P15: PROFESSIONAL MANAGEMENT | Q15: 147 | R15: 28800 | S15: =R15 -> 28800 | X15: 3 | Y15: NENDOS EXTENTION | Z15: G0018 | AA15: PROFESSIONAL MANAGEMENT | AB15: 147 | AC15: 28800 | AD15: =AC15 -> 28800
B16: NENDOS EXTENTION | C16: G0019 | D16: SYED RIZWAN HUSSAIN | E16: 98 | F16: 19600 | G16: =F16 -> 19600 | H16: 46082 | O16: G0019 | P16: SYED RIZWAN HUSSAIN | Q16: 98 | R16: 19600 | S16: =R16 -> 19600 | Z16: G0019 | AA16: SYED RIZWAN HUSSAIN | AB16: 98 | AC16: 19600 | AD16: =AC16 -> 19600
B17: NENDOS EXTENTION | C17: G0020 | D17: SYED ASIF ALI | E17: 98 | F17: 19600 | G17: =F17 -> 19600 | H17: 46082 | O17: G0020 | P17: SYED ASIF ALI | Q17: 98 | R17: 19600 | S17: =R17 -> 19600 | Z17: G0020 | AA17: SYED ASIF ALI | AB17: 98 | AC17: 19600 | AD17: =AC17 -> 19600
B18: NENDOS EXTENTION | C18: G0021 | D18: NIAZ AHMED | E18: 99 | F18: 19800 | G18: =F18 -> 19800 | H18: 46082 | O18: G0021 | P18: NIAZ AHMED | Q18: 96 | R18: 19800 | S18: =R18 -> 19800 | Z18: G0021 | AA18: NIAZ AHMED | AB18: 96 | AC18: 19800 | AD18: =AC18 -> 19800
B19: NENDOS EXTENTION | C19: G0022 | D19: ISRAR AHMED | E19: 96 | F19: 19200 | G19: =F19 -> 19200 | H19: 46082 | O19: G0022 | P19: ISRAR AHMED | Q19: 96 | R19: 19200 | S19: =R19 -> 19200 | Z19: G0022 | AA19: ISRAR AHMED | AB19: 96 | AC19: 19200 | AD19: =AC19 -> 19200
B20: NENDOS EXTENTION | C20: G0023 | D20: MUHAMMAD LAEEQ | E20: 96 | F20: 19200 | G20: =F20 -> 19200 | H20: 46082 | O20: G0023 | P20: MUHAMMAD LAEEQ | Q20: 96 | R20: 19200 | S20: =R20 -> 19200 | Z20: G0023 | AA20: MUHAMMAD LAEEQ | AB20: 96 | AC20: 19200 | AD20: =AC20 -> 19200
B21: NENDOS EXTENTION | C21: G0025 | D21: SYED SAMMER ABBAS ZAIDI | E21: 147 | F21: 29400 | G21: =F21 -> 29400 | H21: 46082 | O21: G0025 | P21: SYED SAMMER ABBAS ZAIDI | Q21: 147 | R21: 29400 | S21: =R21 -> 29400 | Z21: G0025 | AA21: SYED SAMMER ABBAS ZAIDI | AB21: 147 | AC21: 29400 | AD21: =AC21 -> 29400
B22: NENDOS EXTENTION | C22: G0040 | D22: PROFESSIONAL MANAGEMENT | E22: 147 | F22: 29400 | G22: =F22 -> 29400 | H22: 46082 | O22: G0040 | P22: PROFESSIONAL MANAGEMENT | Q22: 147 | R22: 29400 | S22: =R22 -> 29400 | Z22: G0040 | AA22: PROFESSIONAL MANAGEMENT | AB22: 147 | AC22: 29400 | AD22: =AC22 -> 29400
B23: NENDOS EXTENTION | C23: G0041 | D23: MUHAMMAD ABID SALEEM UDDIN | E23: 99 | F23: 19800 | G23: =F23 -> 19800 | H23: 46082 | O23: G0041 | P23: MUHAMMAD ABID SALEEM UDDIN | Q23: 99 | R23: 19800 | S23: =R23 -> 19800 | Z23: G0041 | AA23: MUHAMMAD ABID SALEEM UDDIN | AB23: 99 | AC23: 19800 | AD23: =AC23 -> 19800
B24: NENDOS EXTENTION | C24: G0043 | D24: PROFESSIONAL MANAGEMENT | E24: 192 | F24: 38400 | G24: =F24 -> 38400 | H24: 46082 | O24: G0043 | P24: PROFESSIONAL MANAGEMENT | Q24: 192 | R24: 38400 | S24: =R24 -> 38400 | Z24: G0043 | AA24: PROFESSIONAL MANAGEMENT | AB24: 192 | AC24: 38400 | AD24: =AC24 -> 38400
B25: NENDOS EXTENTION | C25: G0044 | D25: FALAKNAZ GROUP | E25: 96 | F25: 19200 | G25: =F25 -> 19200 | H25: 46082 | O25: G0044 | P25: FALAKNAZ GROUP | Q25: 96 | R25: 19200 | S25: =R25 -> 19200 | Z25: G0044 | AA25: FALAKNAZ GROUP | AB25: 96 | AC25: 19200 | AD25: =AC25 -> 19200
B26: NENDOS EXTENTION | C26: G0045 | D26: PROFESSIONAL MANAGEMENT | E26: 96 | F26: 19200 | G26: =F26 -> 19200 | H26: 46082 | O26: G0045 | P26: PROFESSIONAL MANAGEMENT | Q26: 96 | R26: 19200 | S26: =R26 -> 19200 | Z26: G0045 | AA26: PROFESSIONAL MANAGEMENT | AB26: 96 | AC26: 19200 | AD26: =AC26 -> 19200
A27: 4 | B27: STYLE IN | C27: G0082 | D27: SYED SAIF UR REHMAN | E27: 96 | F27: 28800 | G27: =F27 -> 28800 | H27: 46082 | M27: 4 | N27: BEMBENINE | O27: G0067 | P27: SOHAIL INTIZAR | Q27: 96 | R27: 28800 | S27: 28800 | X27: 4 | Y27: BEMBENINE | Z27: G0067 | AA27: SOHAIL INTIZAR | AB27: 96 | AC27: 28800 | AD27: 28800
A28: 5 | B28: BEMBENINE | C28: G0067 | D28: SOHAIL INTIZAR | E28: 96 | F28: 28800 | G28: 28800 | H28: 46082 | O28: G0068 | P28: MUHAMMAD RAFIQUE BURIRO | Q28: 96 | R28: 28800 | S28: 28800 | Z28: G0068 | AA28: MUHAMMAD RAFIQUE BURIRO | AB28: 96 | AC28: 28800 | AD28: 28800
B29: BEMBENINE | C29: G0068 | D29: MUHAMMAD RAFIQUE BURIRO | E29: 96 | F29: 28800 | G29: 28800 | H29: 46082 | O29: G0069 | P29: KAY KAY GROUP | Q29: 99 | R29: 29700 | S29: 29700 | Z29: G0069 | AA29: KAY KAY GROUP | AB29: 99 | AC29: 29700 | AD29: 29700
B30: BEMBENINE | C30: G0069 | D30: KAY KAY GROUP | E30: 99 | F30: 29700 | G30: 29700 | H30: 46082 | O30: G0071 | P30: KAY KAY GROUP | Q30: 147 | R30: 44100 | S30: 44100 | Z30: G0071 | AA30: KAY KAY GROUP | AB30: 147 | AC30: 44100 | AD30: 44100
B31: BEMBENINE | C31: G0071 | D31: KAY KAY GROUP | E31: 147 | F31: 44100 | G31: 44100 | H31: 46082
E33: =SUM(E4:E31) -> 3138 | M33: TOTAL | R33: =SUM(R4:R30) -> 537400 | S33: =SUM(S4:S30) -> 537400 | X33: TOTAL | AC33: =SUM(AC4:AC30) -> 537400 | AD33: =SUM(AD4:AD30) -> 537400
A34: TOTAL | F34: =SUM(F4:F31) -> 566200 | G34: =SUM(G4:G31) -> 566200
A39: DATE 13-05-2026
A40: ALLOTEE RENT PAYABLE DETAILS
A41: S.NOS. | B41: BRAND NAME | C41: SHOP NOS. | D41: ALLOTEE NAME | E41: SQ.FT. | F41: RENT MONTH OF MARCH-2026 | G41: ALLOTEE RENT PAYABLE | H41: FOR THE MONTH OF MARCH-26 | I41: REMARKS
A42: 1 | B42: ELENOR | C42: G0081 | D42: ALIYA BEGUM | E42: 96 | F42: 14400 | G42: =F42 -> 14400 | H42: 46082
A43: 2 | B43: DOLLAR WORLD | C43: G0026 | D43: FALAKNAZ GROUP | E43: 144 | F43: 14400 | G43: =F43 -> 14400 | H43: 46082
B44: DOLLAR WORLD | C44: G0027 | D44: MUHAMMAD IMRAN | E44: 96 | F44: 9600 | G44: =F44 -> 9600 | H44: 46082
B45: DOLLAR WORLD | C45: G0028 | D45: HAMID ALI | E45: 96 | F45: 9600 | G45: =F45 -> 9600 | H45: 46082
...

Sheet Sheet2
A2: LIST OF ALLOTTEES RENT CHEQUE APPROVAL SHEET
A3: S.NO | B3: DESCRCIPTION | C3: CHEQUE NO | D3: CHEQUE DATE | E3: BANK NAME | F3: AMOUNT
A4: 1 | B4: CHEQUE PAID TO ALLOTEE (RASHID HUSSAIN KHAN ) AGAINST SHOP RENT FOR THE MONTH OF JAN-2026(SHOP #G-59) | C4: 33394909 | E4: DUBAI ISLAMIC BANK | F4: 14400
A5: 2 | B5: CHEQUE PAID TO ALLOTEE (RASHID HUSSAIN KHAN ) AGAINST SHOP RENT FOR THE MONTH OF FEB-2026(SHOP #G-59) | C5: 33394910 | E5: DUBAI ISLAMIC BANK | F5: 14400
A6: 3 | B6: CHEQUE PAID TO ALLOTEE (ABDUL WALI) AGAINST SHOP RENT FOR THE MONTH OF JAN-2026(SHOP #G-60) | C6: 33394911 | E6: DUBAI ISLAMIC BANK | F6: 14400
A7: 4 | B7: CHEQUE PAID TO ALLOTEE (ABDUL WALI) AGAINST SHOP RENT FOR THE MONTH OF FEB-2026(SHOP #G-60) | C7: 33394912 | E7: DUBAI ISLAMIC BANK | F7: 14400
A8: 5 | B8: CHEQUE PAID TO ALLOTEE (TALAT ASHFAQ QURESHI) AGAINST SHOP RENT FOR THE MONTH OF FEB-2026(SHOP #G-50) | C8: 33394913 | D8: OK | E8: DUBAI ISLAMIC BANK | F8: 17280
A9: 6 | B9: CHEQUE PAID TO ALLOTEE (MUHAMMAD IMRAN) AGAINST SHOP RENT FOR THE MONTH OF JAN-2026(SHOP #G-27) | C9: 33394914 | E9: DUBAI ISLAMIC BANK | F9: 9600
A10: 7 | B10: CHEQUE PAID TO ALLOTEE (MUHAMMAD IMRAN) AGAINST SHOP RENT FOR THE MONTH OF FEB-2026(SHOP #G-27) | C10: 33394915 | E10: DUBAI ISLAMIC BANK | F10: 9600
A11: 8 | B11: CHEQUE PAID TO ALLOTEE (HAMID ALI ) AGAINST SHOP RENT FOR THE MONTH OF JAN-2026(SHOP #G-28) | C11: 33394916 | E11: DUBAI ISLAMIC BANK | F11: 9600
A12: 9 | B12: CHEQUE PAID TO ALLOTEE (HAMID ALI ) AGAINST SHOP RENT FOR THE MONTH OF FEB-2026(SHOP #G-28) | C12: 33394917 | E12: DUBAI ISLAMIC BANK | F12: 9600
A13: 10 | B13: CHEQUE PAID TO ALLOTEE (ASHFAQ AHMED SIDDIQUI ) AGAINST SHOP RENT FOR THE MONTH OF JAN-2026(SHOP #G-31) | C13: 33394918 | E13: DUBAI ISLAMIC BANK | F13: 11800
A14: 11 | B14: CHEQUE PAID TO ALLOTEE (ASHFAQ AHMED SIDDIQUI ) AGAINST SHOP RENT FOR THE MONTH OF FEB-2026(SHOP #G-31) | C14: 33394919 | E14: DUBAI ISLAMIC BANK | F14: 11800
A15: 12 | B15: CHEQUE PAID TO ALLOTEE (ASHFAQ AHMED SIDDIQUI ) AGAINST SHOP RENT FOR THE MONTH OF JAN-2026(SHOP #G-32) | C15: 33394920 | E15: DUBAI ISLAMIC BANK | F15: 11800
A16: 13 | B16: CHEQUE PAID TO ALLOTEE (ASHFAQ AHMED SIDDIQUI ) AGAINST SHOP RENT FOR THE MONTH OF FEB-2026(SHOP #G-32) | C16: 33394921 | E16: DUBAI ISLAMIC BANK | F16: 11800
A17: 14 | B17: CHEQUE PAID TO ALLOTEE (DANISH AHMED SIDDIQUI ) AGAINST SHOP RENT FOR THE MONTH OF JAN-2026(SHOP #G-34) | C17: 33394922 | D17: OK | E17: DUBAI ISLAMIC BANK | F17: 9600
A18: 15 | B18: CHEQUE PAID TO ALLOTEE (DANISH AHMED SIDDIQUI ) AGAINST SHOP RENT FOR THE MONTH OF FEB-2026(SHOP #G-34) | C18: 33394923 | D18: OK | E18: DUBAI ISLAMIC BANK | F18: 9600
A19: TOTAL AMOUNT | F19: =SUM(F4:F18) -> 179680
B26: PREPAID BY | D26: CHECKED BY
B33: VERIFIED BY | D33: APPROVED BY
A39: LIST OF ALLOTTEES RENT CHEQUE APPROVAL SHEET
A40: S.NO | B40: DESCRCIPTION | C40: CHEQUE NO | D40: CHEQUE DATE | E40: BANK NAME | F40: AMOUNT
A41: 1 | B41: CHEQUE PAID TO ALLOTEE (AZHAR ALI ) AGAINST SHOP RENT FOR THE MONTH OF JAN-2026(SHOP #G-37) | C41: 33394924 | E41: DUBAI ISLAMIC BANK | F41: 9600
A42: 2 | B42: CHEQUE PAID TO ALLOTEE (AZHAR ALI ) AGAINST SHOP RENT FOR THE MONTH OF FEB-2026(SHOP #G-37) | C42: 33394925 | E42: DUBAI ISLAMIC BANK | F42: 9600
A43: 3 | B43: CHEQUE PAID TO ALLOTEE (ASIM QURESHI /SAQIB QURESHI ) AGAINST SHOP RENT FOR THE MONTH OF JAN-2026(SHOP #G-30) | C43: 33394926 | E43: DUBAI ISLAMIC BANK | F43: 9600
A44: 4 | B44: CHEQUE PAID TO ALLOTEE (ASIM QURESHI /SAQIB QURESHI ) AGAINST SHOP RENT FOR THE MONTH OF FEB-2026(SHOP #G-30) | C44: 33394927 | E44: DUBAI ISLAMIC BANK | F44: 9600
A45: 5 | B45: CHEQUE PAID TO ALLOTEE (SOHAIL INTEZAR ) AGAINST SHOP RENT FOR THE MONTH OF JAN-2026(SHOP #G-67) | C45: 33394928 | E45: DUBAI ISLAMIC BANK | F45: 28800
A46: 6 | B46: CHEQUE PAID TO ALLOTEE (SOHAIL INTEZAR ) AGAINST SHOP RENT FOR THE MONTH OF FEB-2026(SHOP #G-67) | C46: 33394929 | E46: DUBAI ISLAMIC BANK | F46: 28800
A47: 7 | B47: CHEQUE PAID TO ALLOTEE (MUHAMMAD RAFIQUE BURIRO ) AGAINST SHOP RENT FOR THE MONTH OF JAN-2026(SHOP #G-68) | C47: 33394930 | E47: DUBAI ISLAMIC BANK | F47: 28800
A48: 8 | B48: CHEQUE PAID TO ALLOTEE (MUHAMMAD RAFIQUE BURIRO ) AGAINST SHOP RENT FOR THE MONTH OF FEB-2026(SHOP #G-68) | C48: 33394931 | E48: DUBAI ISLAMIC BANK | F48: 28800
A49: 9 | B49: CHEQUE PAID TO ALLOTEE (SYED RIZWAN HUSSAIN) AGAINST SHOP RENT FOR THE MONTH OF FEB-2026(SHOP #G-19) | C49: 33394932 | E49: DUBAI ISLAMIC BANK | F49: 19600
A50: 10 | B50: CHEQUE PAID TO ALLOTEE (SYED ASIF ALI ) AGAINST SHOP RENT FOR THE MONTH OF FEB-2026(SHOP #G-20) | C50: 33394933 | E50: DUBAI ISLAMIC BANK | F50: 19600
A51: 11 | B51: CHEQUE PAID TO ALLOTEE (NIAZ AHMED ) AGAINST SHOP RENT FOR THE MONTH OF FEB-2026(SHOP #G-21) | C51: 33394934 | E51: DUBAI ISLAMIC BANK | F51: 19800
A52: 12 | B52: CHEQUE PAID TO ALLOTEE (ISRAR AHMED ) AGAINST SHOP RENT FOR THE MONTH OF FEB-2026(SHOP #G-22) | C52: 33394935 | E52: DUBAI ISLAMIC BANK | F52: 19200
... A55: 15 | B55: CHEQUE PAID TO ALLOTEE (MUHAMMAD ABID SALEEM UDDIN ) AGAINST SHOP RENT FOR THE MONTH OF FEB-2026(SHOP #G-41) | C55: 33394938 | E55: DUBAI ISLAMIC BANK | F55: 19800
A56: TOTAL AMOUNT | F56: =SUM(F41:F55) -> 300200
B64: PREPAID BY | D64: CHECKED BY
B71: VERIFIED BY | D71: APPROVED BY
A83: LIST OF ALLOTTEES RENT CHEQUE APPROVAL SHEET
A84: S.NO | B84: DESCRCIPTION | C84: CHEQUE NO | D84: CHEQUE DATE | E84: BANK NAME | F84: AMOUNT
...

Sheet ALLOTEE RENT PAYABLES
A2: BRAND SECURITY DEPOSIT AND ADVANCE RENT AND RENT DETAILS | S2: ALLOTEE RENT DETAILS
B3: S.NO | C3: BRAND NAME | D3: SHOP NO | E3: ALLOTEE NAME | F3: SQ.FT | G3: SECURITY DEPOSIT | H3: ADVANCE RENT DEPOSIT | I3: TOTAL SECURITY DEPOSIT AND ADVANCE RENT | J3: RENT MONTH OF DEC-2026 | K3: RENT MONTH OF JAN-2026 | L3: RENT MONTH OF FEB-2026 | M3: TOTAL ADVANCE RENT PAYABLE | N3: RENT MONTH OF MARCH-2026 | O3: RENT MONTH OF APRIL-2026 | P3: RENT MONTH OF MAY-2026 | Q3: RENT MONTH OF JUN-2026 | R3: TOTAL ADVANCE RENT PAYABLE | S3: ALLOTEE RENT PAYABLE DEC-2025 | T3: ALLOTEE RENT PAYABLE JAN-2026 | U3: ALLOTEE RENT PAYABLE FEB-2026 | V3: RENT PAID TO ALLOTEE | W3: TOTAL RENT PAYABLE TO ALLOTEE | X3: REMARKS | Y3: RENT START DATE
